Workbook

Sheet Problema

Sheet Base Original
B2: Tabela 1: Identificação dos tratamentos pelas combinações dos níveis dos fatores
B4: Tratamento | C4: Combinação dos fatores
B5: 01 | C5: AAA | E5: 1º fator: solado (A = quatro fixadores, B = seis fixadores e C = oito fixadores)
B6: 02 | C6: BAA | E6: 2ª fator: firmeza (A = macio, B = rígido)
B7: 03 | C7: CAA | E7: 3º fator: cadarço (A = com cadarço, B = sem cadarço)
B8: 04 | C8: ABA
B9: 05 | C9: BBA
B10: 06 | C10: CBA
B11: 07 | C11: ABB
B12: 08 | C12: BBB
B13: 09 | C13: CBB
B14: 10 | C14: AAB
B15: 11 | C15: BAB
B16: 12 | C16: CAB
B20: Tabela 2: valores das respostas (tempo dos corredores em 200 m)
C22: HORÁRIO
C23: 1 | D23: 2 | E23: 3 | F23: 4 | G23: 5 | H23: 6 | I23: 7 | J23: 8 | K23: 9 | L23: 10 | M23: 11 | N23: 12
A24: PISTA | B24: 1 | C24: 22.67 | D24: 23.73 | E24: 24.48 | F24: 25.68 | G24: 23.21 | H24: 25.96 | I24: 25.94 | J24: 25.96 | K24: 24.84 | L24: 24.56 | M24: 25.27 | N24: 23.61
C25: 22.97 | D25: 23.56 | E25: 25.57 | F25: 23.77 | G25: 23.37 | H25: 24.9 | I25: 23.41 | J25: 24.55 | K25: 24.33 | L25: 24.52 | M25: 26.13 | N25: 25.29
B26: 2 | C26: 25.43 | D26: 25.3 | E26: 23.42 | F26: 25.49 | G26: 23.56 | H26: 24.07 | I26: 25.63 | J26: 24.36 | K26: 24.55 | L26: 24.04 | M26: 24.08 | N26: 24.18
C27: 23.46 | D27: 23.7 | E27: 24.14 | F27: 24.18 | G27: 24.04 | H27: 24.84 | I27: 26.07 | J27: 24.68 | K27: 25.64 | L27: 25.57 | M27: 25.79 | N27: 24.24
B28: =B26+1 -> 3 | C28: 23.99 | D28: 23.39 | E28: 24.71 | F28: 23.47 | G28: 23.77 | H28: 24.18 | I28: 24.04 | J28: 23.8 | K28: 24.4 | L28: 25.51 | M28: 24.14 | N28: 24.12
C29: 23.98 | D29: 24.28 | E29: 26.14 | F29: 24.08 | G29: 22.77 | H29: 23.58 | I29: 25.28 | J29: 23.34 | K29: 23.55 | L29: 25.01 | M29: 25.05 | N29: 24.06
B30: =B28+1 -> 4 | C30: 23.67 | D30: 23.43 | E30: 22.85 | F30: 24 | G30: 23.31 | H30: 25.24 | I30: 23.56 | J30: 24.92 | K30: 26.51 | L30: 24.5 | M30: 25.94 | N30: 24.08
C31: 24.59 | D31: 24.04 | E31: 23.42 | F31: 23.33 | G31: 24.37 | H31: 24.16 | I31: 23.61 | J31: 23.4 | K31: 25.25 | L31: 24.71 | M31: 24.58 | N31: 25.75
B32: =B30+1 -> 5 | C32: 24.57 | D32: 24.55 | E32: 25.24 | F32: 24.64 | G32: 23.42 | H32: 24.15 | I32: 23.43 | J32: 23.98 | K32: 25.54 | L32: 25.23 | M32: 23.44 | N32: 26.54
C33: 24.37 | D33: 23.38 | E33: 23.88 | F33: 25.73 | G33: 24.94 | H33: 23.64 | I33: 24.64 | J33: 23.47 | K33: 23 | L33: 25.19 | M33: 25.01 | N33: 25.81
B34: =B32+1 -> 6 | C34: 23.27 | D34: 24.53 | E34: 25.47 | F34: 23.69 | G34: 24.97 | H34: 24.5 | I34: 22.93 | J34: 24.39 | K34: 25.69 | L34: 25.7 | M34: 23.43 | N34: 26.28
C35: 22.81 | D35: 25.86 | E35: 24.52 | F35: 22.42 | G35: 22.84 | H35: 25.19 | I35: 23.42 | J35: 23.18 | K35: 24.37 | L35: 23.4 | M35: 23.58 | N35: 26.35
B36: =B34+1 -> 7 | C36: 23.81 | D36: 23.86 | E36: 23.17 | F36: 23.4 | G36: 24.24 | H36: 24.64 | I36: 24.46 | J36: 25.84 | K36: 23.87 | L36: 23.73 | M36: 23.13 | N36: 26.41
C37: 24.8 | D37: 24.31 | E37: 23.28 | F37: 23.58 | G37: 24 | H37: 24.51 | I37: 24.97 | J37: 24.19 | K37: 23.86 | L37: 23.42 | M37: 23.1 | N37: 23.87
B38: =B36+1 -> 8 | C38: 24.06 | D38: 22.62 | E38: 23.24 | F38: 23.98 | G38: 25.57 | H38: 23.84 | I38: 22.78 | J38: 25.39 | K38: 24.35 | L38: 25.5 | M38: 24.2 | N38: 25.11
C39: 22.58 | D39: 25.43 | E39: 25.34 | F39: 24.91 | G39: 24.3 | H39: 23.85 | I39: 23.73 | J39: 23.55 | K39: 24.1 | L39: 25.2 | M39: 25.19 | N39: 24.48
B40: =B38+1 -> 9 | C40: 23.08 | D40: 24.74 | E40: 24.51 | F40: 22.37 | G40: 24.33 | H40: 24.78 | I40: 23.33 | J40: 23.45 | K40: 24.08 | L40: 23.12 | M40: 24.34 | N40: 25.89
C41: 23.24 | D41: 23.05 | E41: 22.54 | F41: 24.55 | G41: 23.78 | H41: 24.2 | I41: 25.46 | J41: 23.19 | K41: 22.61 | L41: 24.76 | M41: 24.15 | N41: 24.19
B42: =B40+1 -> 10 | C42: 24.45 | D42: 22.94 | E42: 23.21 | F42: 24.65 | G42: 23.33 | H42: 24.29 | I42: 25.99 | J42: 25 | K42: 25.61 | L42: 23.36 | M42: 24.44 | N42: 23.93
C43: 24.25 | D43: 25.05 | E43: 23.32 | F43: 25.2 | G43: 23.64 | H43: 24.18 | I43: 25.72 | J43: 23.42 | K43: 24.68 | L43: 23.04 | M43: 24.41 | N43: 25.6
B44: =B42+1 -> 11 | C44: 24.59 | D44: 23.39 | E44: 24.43 | F44: 22.5 | G44: 23.25 | H44: 22.43 | I44: 22.85 | J44: 23.36 | K44: 24.03 | L44: 25.14 | M44: 25.13 | N44: 25.23
C45: 22.43 | D45: 24.2 | E45: 25.1 | F45: 23.89 | G45: 25.19 | H45: 25.05 | I45: 26.02 | J45: 24.29 | K45: 25.2 | L45: 24.53 | M45: 24.63 | N45: 25.32
B46: =B44+1 -> 12 | C46: 22.5 | D46: 23.18 | E46: 23.07 | F46: 24.97 | G46: 22.55 | H46: 23.78 | I46: 25.12 | J46: 22.73 | K46: 25.01 | L46: 24.7 | M46: 25.78 | N46: 22.8
...

Sheet Tabela
R1: Bases de Cálculo para as Somas de Quadrados | AJ1: Estimativas para os parâmetros
B2: Pista(Linhas) | C2: Horario(Colunas) | D2: Pistas:Horario | E2: Tratamentos | F2: Trat | G2: Solado | H2: Firmeza | I2: Cadarço | J2: Sol,Fir | K2: Sol,Cad | L2: Fir,Cad | M2: Resposta | O2: Fonte | P2: Niveis | W2: r(Réplicas) | X2: P(Linhas) | Y2: C(Colunas) | AA2: Fonte | AB2: SQ | AC2: GL | AD2: QM | AE2: F | AF2: P-valor
B3: 01 | C3: 01 | D3: =B3&C3 -> 0101 | E3: 10 | F3: =VLOOKUP(E3,'Base Original'!$B$4:$C$16,2,0) -> AAB | G3: =LEFT(F3,1) -> A | H3: =MID(F3,2,1) -> A | I3: =RIGHT(F3,1) -> B | J3: =G3&H3 -> AA | K3: =G3&I3 -> AB | L3: =H3&I3 -> AB | M3: 22.67 | O3: Trat | P3: 12 | R3: Pistas | S3: Total | T3: Total^2 | U3: n | W3: 2 | X3: 12 | Y3: 12 | AA3: Trat | AB3: =AB4+AB5+AB6+AB8+AB10+AB12+AB14 -> 50.973218 | AC3: =P3-1 -> 11 | AD3: =IFERROR(AB3/AC3,"-") -> 4.6339289 | AE3: =IFERROR(AD3/$AD$17,"-") -> 6.9749813 | AF3: =IFERROR(_xlfn.F.DIST.RT(AE3,AC3,$AC$17),"-") -> 2.6814904e-10 | AI3: Média Global: | AJ3: =AVERAGE(M3:M290) -> 24.250312
B4: 01 | C4: 02 | D4: =B4&C4 -> 0102 | E4: 07 | F4: =VLOOKUP(E4,'Base Original'!$B$4:$C$16,2,0) -> ABB | G4: =LEFT(F4,1) -> A | H4: =MID(F4,2,1) -> B | I4: =RIGHT(F4,1) -> B | J4: =G4&H4 -> AB | K4: =G4&I4 -> AB | L4: =H4&I4 -> BB | M4: 23.73 | O4: Pistas | P4: 12 | R4: 01 | S4: =SUMIFS($M$3:$M$290,$B$3:$B$290,R4) -> 588.28 | T4: =S4^2 -> 346073.36 | U4: 24 | W4: N | X4: =W3*X3*Y3 -> 288 | AA4: Solado | AB4: =SUM(T46:T48)/U46-SUM(S46:S48)^2/X4 -> 4.2390896 | AC4: =P6-1 -> 2 | AD4: =IFERROR(AB4/AC4,"-") -> 2.1195448 | AE4: =IFERROR(AD4/$AD$17,"-") -> 3.190335 | AF4: =IFERROR(_xlfn.F.DIST.RT(AE4,AC4,$AC$17),"-") -> 0.042812642
B5: 01 | C5: 03 | D5: =B5&C5 -> 0103 | E5: 06 | F5: =VLOOKUP(E5,'Base Original'!$B$4:$C$16,2,0) -> CBA | G5: =LEFT(F5,1) -> C | H5: =MID(F5,2,1) -> B | I5: =RIGHT(F5,1) -> A | J5: =G5&H5 -> CB | K5: =G5&I5 -> CA | L5: =H5&I5 -> BA | M5: 24.48 | O5: Hora | P5: 12 | R5: 02 | S5: =SUMIFS($M$3:$M$290,$B$3:$B$290,R5) -> 590.46 | T5: =S5^2 -> 348643.01 | U5: 24 | AA5: Firmeza | AB5: =SUM(T51:T52)/U51-SUM(S51:S52)^2/X4 -> 2.2773337 | AC5: =P7-1 -> 1 | AD5: =IFERROR(AB5/AC5,"-") -> 2.2773337 | AE5: =IFERROR(AD5/$AD$17,"-") -> 3.4278385 | AF5: =IFERROR(_xlfn.F.DIST.RT(AE5,AC5,$AC$17),"-") -> 0.065266578 | AI5: i/j | AJ5: 01 | AK5: 02 | AL5: 03 | AM5: 04 | AN5: 05 | AO5: 06 | AP5: 07 | AQ5: 08 | AR5: 09 | AS5: 10 | AT5: 11 | AU5: 12
B6: 01 | C6: 04 | D6: =B6&C6 -> 0104 | E6: 09 | F6: =VLOOKUP(E6,'Base Original'!$B$4:$C$16,2,0) -> CBB | G6: =LEFT(F6,1) -> C | H6: =MID(F6,2,1) -> B | I6: =RIGHT(F6,1) -> B | J6: =G6&H6 -> CB | K6: =G6&I6 -> CB | L6: =H6&I6 -> BB | M6: 25.68 | O6: Solado | P6: 3 | R6: 03 | S6: =SUMIFS($M$3:$M$290,$B$3:$B$290,R6) -> 580.64 | T6: =S6^2 -> 337142.81 | U6: 24 | AA6: Cadarço | AB6: =SUM($T$55:$T$56)/U55-SUM(S55:S56)^2/X4 -> 17.086884 | AC6: =P8-1 -> 1 | AD6: =IFERROR(AB6/AC6,"-") -> 17.086884 | AE6: =IFERROR(AD6/$AD$17,"-") -> 25.719146 | AF6: =IFERROR(_xlfn.F.DIST.RT(AE6,AC6,$AC$17),"-") -> 7.6225435e-07 | AI6: Pista(Linhas) | AJ6: =AVERAGEIFS($M$3:$M$290,$B$3:$B$290,AJ$5)-$AJ$3 -> 0.26135417 | AK6: =AVERAGEIFS($M$3:$M$290,$B$3:$B$290,AK$5)-$AJ$3 -> 0.3521875 | AL6: =AVERAGEIFS($M$3:$M$290,$B$3:$B$290,AL$5)-$AJ$3 -> -0.056979167 | AM6: =AVERAGEIFS($M$3:$M$290,$B$3:$B$290,AM$5)-$AJ$3 -> 0.050520833 | AN6: =AVERAGEIFS($M$3:$M$290,$B$3:$B$290,AN$5)-$AJ$3 -> 0.2409375 | AO6: =AVERAGEIFS($M$3:$M$290,$B$3:$B$290,AO$5)-$AJ$3 -> 0.032604167 | AP6: =AVERAGEIFS($M$3:$M$290,$B$3:$B$290,AP$5)-$AJ$3 -> -0.14822917 | AQ6: =AVERAGEIFS($M$3:$M$290,$B$3:$B$290,AQ$5)-$AJ$3 -> 0.053854167 | ... AU6: =AVERAGEIFS($M$3:$M$290,$B$3:$B$290,AU$5)-$AJ$3 -> -0.51989583
B7: 01 | C7: 05 | D7: =B7&C7 -> 0105 | E7: 03 | F7: =VLOOKUP(E7,'Base Original'!$B$4:$C$16,2,0) -> CAA | G7: =LEFT(F7,1) -> C | H7: =MID(F7,2,1) -> A | I7: =RIGHT(F7,1) -> A | J7: =G7&H7 -> CA | K7: =G7&I7 -> CA | L7: =H7&I7 -> AA | M7: 23.21 | O7: Firmeza | P7: 2 | R7: 04 | S7: =SUMIFS($M$3:$M$290,$B$3:$B$290,R7) -> 583.22 | T7: =S7^2 -> 340145.57 | U7: 24 | AA7: (Sol,Fir) | AB7: =SUM($T$59:$T$64)/$U$59-SUM(S59:$S$64)^2/$X$4 -> 14.572691 | AC7: - | AD7: =IFERROR(AB7/AC7,"-") -> - | AE7: =IFERROR(AD7/$AD$17,"-") -> - | AF7: =IFERROR(_xlfn.F.DIST.RT(AE7,AC7,$AC$17),"-") -> - | AI7: Horario(Colunas) | AJ7: =AVERAGEIFS($M$3:$M$290,$C$3:$C$290,AJ$5)-$AJ$3 -> -0.50697917 | AK7: =AVERAGEIFS($M$3:$M$290,$C$3:$C$290,AK$5)-$AJ$3 -> -0.22572917 | AL7: =AVERAGEIFS($M$3:$M$290,$C$3:$C$290,AL$5)-$AJ$3 -> -0.15739583 | AM7: =AVERAGEIFS($M$3:$M$290,$C$3:$C$290,AM$5)-$AJ$3 -> -0.20614583 | AN7: =AVERAGEIFS($M$3:$M$290,$C$3:$C$290,AN$5)-$AJ$3 -> -0.4328125 | AO7: =AVERAGEIFS($M$3:$M$290,$C$3:$C$290,AO$5)-$AJ$3 -> 0.1134375 | AP7: =AVERAGEIFS($M$3:$M$290,$C$3:$C$290,AP$5)-$AJ$3 -> 0.1809375 | AQ7: =AVERAGEIFS($M$3:$M$290,$C$3:$C$290,AQ$5)-$AJ$3 -> -0.22697917 | ... AU7: =AVERAGEIFS($M$3:$M$290,$C$3:$C$290,AU$5)-$AJ$3 -> 0.6646875
B8: 01 | C8: 06 | D8: =B8&C8 -> 0106 | E8: 04 | F8: =VLOOKUP(E8,'Base Original'!$B$4:$C$16,2,0) -> ABA | G8: =LEFT(F8,1) -> A | H8: =MID(F8,2,1) -> B | I8: =RIGHT(F8,1) -> A | J8: =G8&H8 -> AB | K8: =G8&I8 -> AA | L8: =H8&I8 -> BA | M8: 25.96 | O8: Cadarço | P8: 2 | R8: 05 | S8: =SUMIFS($M$3:$M$290,$B$3:$B$290,R8) -> 587.79 | T8: =S8^2 -> 345497.08 | U8: 24 | AA8: (Sol x Fir) | AB8: =AB7-AB4-AB5 -> 8.0562674 | AC8: =AC4*AC5 -> 2 | AD8: =IFERROR(AB8/AC8,"-") -> 4.0281337 | AE8: =IFERROR(AD8/$AD$17,"-") -> 6.0631395 | AF8: =IFERROR(_xlfn.F.DIST.RT(AE8,AC8,$AC$17),"-") -> 0.002677542
B9: 01 | C9: 07 | D9: =B9&C9 -> 0107 | E9: 12 | F9: =VLOOKUP(E9,'Base Original'!$B$4:$C$16,2,0) -> CAB | G9: =LEFT(F9,1) -> C | H9: =MID(F9,2,1) -> A | I9: =RIGHT(F9,1) -> B | J9: =G9&H9 -> CA | K9: =G9&I9 -> CB | L9: =H9&I9 -> AB | M9: 25.94 | R9: 06 | S9: =SUMIFS($M$3:$M$290,$B$3:$B$290,R9) -> 582.79 | T9: =S9^2 -> 339644.18 | U9: 24 | AA9: (Sol,Cad) | AB9: =SUM($T$67:$T$72)/$U$67-SUM(S67:$S$72)^2/$X$4 -> 37.025611 | AC9: - | AD9: =IFERROR(AB9/AC9,"-") -> - | AE9: =IFERROR(AD9/$AD$17,"-") -> - | AF9: =IFERROR(_xlfn.F.DIST.RT(AE9,AC9,$AC$17),"-") -> - | AI9: Tratamentos
B10: 01 | C10: 08 | D10: =B10&C10 -> 0108 | E10: 05 | F10: =VLOOKUP(E10,'Base Original'!$B$4:$C$16,2,0) -> BBA | G10: =LEFT(F10,1) -> B | H10: =MID(F10,2,1) -> B | I10: =RIGHT(F10,1) -> A | J10: =G10&H10 -> BB | K10: =G10&I10 -> BA | L10: =H10&I10 -> BA | M10: 25.96 | R10: 07 | S10: =SUMIFS($M$3:$M$290,$B$3:$B$290,R10) -> 578.45 | T10: =S10^2 -> 334604.4 | U10: 24 | AA10: (Sol x Cad) | AB10: =AB9-AB4-AB6 -> 15.699638 | AC10: =AC4*AC6 -> 2 | AD10: =IFERROR(AB10/AC10,"-") -> 7.8498191 | AE10: =IFERROR(AD10/$AD$17,"-") -> 11.815533 | AF10: =IFERROR(_xlfn.F.DIST.RT(AE10,AC10,$AC$17),"-") -> 1.240047e-05 | AI10: Solado | AJ10: Estimativas | AK10: Firmeza | AL10: Estimativas | AM10: Cadarço | AN10: Estimativas
B11: 01 | C11: 09 | D11: =B11&C11 -> 0109 | E11: 08 | F11: =VLOOKUP(E11,'Base Original'!$B$4:$C$16,2,0) -> BBB | G11: =LEFT(F11,1) -> B | H11: =MID(F11,2,1) -> B | I11: =RIGHT(F11,1) -> B | J11: =G11&H11 -> BB | K11: =G11&I11 -> BB | L11: =H11&I11 -> BB | M11: 24.84 | R11: 08 | S11: =SUMIFS($M$3:$M$290,$B$3:$B$290,R11) -> 583.3 | T11: =S11^2 -> 340238.89 | U11: 24 | AA11: (Fir, Cad) | AB11: =SUM($T$75:$T$78)/$U$75-SUM(S75:$S$78)^2/$X$4 -> 19.418943 | AC11: - | AD11: =IFERROR(AB11/AC11,"-") -> - | AE11: =IFERROR(AD11/$AD$17,"-") -> - | AF11: =IFERROR(_xlfn.F.DIST.RT(AE11,AC11,$AC$17),"-") -> - | AI11: A | AJ11: =AVERAGEIFS($M$3:$M$290,$G$3:$G$290,AI11)-$AJ$3 -> 0.17072917 | AK11: A | AL11: =AVERAGEIFS($M$3:$M$290,$H$3:$H$290,AK11)-$AJ$3 -> -0.088923611 | AM11: A | AN11: =AVERAGEIFS($M$3:$M$290,$I$3:$I$290,AM11)-$AJ$3 -> 0.24357639
B12: 01 | C12: 10 | D12: =B12&C12 -> 0110 | E12: 02 | F12: =VLOOKUP(E12,'Base Original'!$B$4:$C$16,2,0) -> BAA | G12: =LEFT(F12,1) -> B | H12: =MID(F12,2,1) -> A | I12: =RIGHT(F12,1) -> A | J12: =G12&H12 -> BA | K12: =G12&I12 -> BA | L12: =H12&I12 -> AA | M12: 24.56 | R12: 09 | S12: =SUMIFS($M$3:$M$290,$B$3:$B$290,R12) -> 573.74 | T12: =S12^2 -> 329177.59 | U12: 24 | AA12: (Fir, Cad) | AB12: =AB11-AB5-AB6 -> 0.054725347 | AC12: =AC5*AC6 -> 1 | AD12: =IFERROR(AB12/AC12,"-") -> 0.054725347 | AE12: =IFERROR(AD12/$AD$17,"-") -> 0.082372493 | AF12: =IFERROR(_xlfn.F.DIST.RT(AE12,AC12,$AC$17),"-") -> 0.77434165 | AI12: B | AJ12: =AVERAGEIFS($M$3:$M$290,$G$3:$G$290,AI12)-$AJ$3 -> -0.10010417 | AK12: B | AL12: =AVERAGEIFS($M$3:$M$290,$H$3:$H$290,AK12)-$AJ$3 -> 0.088923611 | AM12: B | AN12: =AVERAGEIFS($M$3:$M$290,$I$3:$I$290,AM12)-$AJ$3 -> -0.24357639
B13: 01 | C13: 11 | D13: =B13&C13 -> 0111 | E13: 01 | F13: =VLOOKUP(E13,'Base Original'!$B$4:$C$16,2,0) -> AAA | G13: =LEFT(F13,1) -> A | H13: =MID(F13,2,1) -> A | I13: =RIGHT(F13,1) -> A | J13: =G13&H13 -> AA | K13: =G13&I13 -> AA | L13: =H13&I13 -> AA | M13: 25.27 | R13: 10 | S13: =SUMIFS($M$3:$M$290,$B$3:$B$290,R13) -> 583.71 | T13: =S13^2 -> 340717.36 | U13: 24 | AA13: (Sol,Fir,Cad)=Trat | AB13: =SUM($T$81:$T$92)/U81-SUM($S$81:$S$92)^2/$X$4 -> 50.973218 | AC13: - | AD13: =IFERROR(AB13/AC13,"-") -> - | AE13: =IFERROR(AD13/$AD$17,"-") -> - | AF13: =IFERROR(_xlfn.F.DIST.RT(AE13,AC13,$AC$17),"-") -> - | AI13: C | AJ13: =AVERAGEIFS($M$3:$M$290,$G$3:$G$290,AI13)-$AJ$3 -> -0.070625
B14: 01 | C14: 12 | D14: =B14&C14 -> 0112 | E14: 11 | F14: =VLOOKUP(E14,'Base Original'!$B$4:$C$16,2,0) -> BAB | G14: =LEFT(F14,1) -> B | H14: =MID(F14,2,1) -> A | I14: =RIGHT(F14,1) -> B | J14: =G14&H14 -> BA | K14: =G14&I14 -> BB | L14: =H14&I14 -> AB | M14: 23.61 | R14: 11 | S14: =SUMIFS($M$3:$M$290,$B$3:$B$290,R14) -> 582.18 | T14: =S14^2 -> 338933.55 | U14: 24 | AA14: (Sol x Fir x Cad) | AB14: =AB13-AB4-AB5-AB6-AB8-AB10-AB12 -> 3.5592799 | AC14: =AC4*AC5*AC6 -> 2 | AD14: =IFERROR(AB14/AC14,"-") -> 1.7796399 | AE14: =IFERROR(AD14/$AD$17,"-") -> 2.6787108 | AF14: =IFERROR(_xlfn.F.DIST.RT(AE14,AC14,$AC$17),"-") -> 0.070591053
B15: 01 | C15: 01 | D15: =B15&C15 -> 0101 | E15: 10 | F15: =VLOOKUP(E15,'Base Original'!$B$4:$C$16,2,0) -> AAB | G15: =LEFT(F15,1) -> A | H15: =MID(F15,2,1) -> A | I15: =RIGHT(F15,1) -> B | J15: =G15&H15 -> AA | K15: =G15&I15 -> AB | L15: =H15&I15 -> AB | M15: 22.97 | R15: 12 | S15: =SUMIFS($M$3:$M$290,$B$3:$B$290,R15) -> 569.53 | T15: =S15^2 -> 324364.42 | U15: 24 | AA15: Pistas | AB15: 16.228043 | AC15: =P4-1 -> 11 | AD15: =IFERROR(AB15/AC15,"-") -> 1.4752766 | AE15: =IFERROR(AD15/$AD$17,"-") -> 2.2205837 | AF15: =IFERROR(_xlfn.F.DIST.RT(AE15,AC15,$AC$17),"-") -> 0.013918674 | AI15: Interações
B16: 01 | C16: 02 | D16: =B16&C16 -> 0102 | E16: 07 | F16: =VLOOKUP(E16,'Base Original'!$B$4:$C$16,2,0) -> ABB | G16: =LEFT(F16,1) -> A | H16: =MID(F16,2,1) -> B | I16: =RIGHT(F16,1) -> B | J16: =G16&H16 -> AB | K16: =G16&I16 -> AB | L16: =H16&I16 -> BB | M16: 23.56 | AA16: Hora | AB16: =SUM(T18:T29)/U18-SUM(S18:S29)^2/X4 -> 31.648268 | AC16: =P5-1 -> 11 | AD16: =IFERROR(AB16/AC16,"-") -> 2.8771152 | AE16: =IFERROR(AD16/$AD$17,"-") -> 4.3306286 | AF16: =IFERROR(_xlfn.F.DIST.RT(AE16,AC16,$AC$17),"-") -> 6.1366178e-06 | AI16: Sol x Fir | AJ16: Estimativas | AK16: Sol x Cad | AL16: Estimativas | AM16: Fir x Cad | AN16: Estimativas | AO16: Sol x Fir x Cad | AP16: Estimativas
B17: 01 | C17: 03 | D17: =B17&C17 -> 0103 | E17: 06 | F17: =VLOOKUP(E17,'Base Original'!$B$4:$C$16,2,0) -> CBA | G17: =LEFT(F17,1) -> C | H17: =MID(F17,2,1) -> B | I17: =RIGHT(F17,1) -> A | J17: =G17&H17 -> CB | K17: =G17&I17 -> CA | L17: =H17&I17 -> BA | M17: 25.57 | R17: Horarios | S17: Total | T17: Total^2 | U17: n | AA17: Erro | AB17: =AB18-AB20-AB16-AB15-AB3 -> 168.74854 | AC17: =AC18-AC16-AC15-AC3 -> 254 | AD17: =IFERROR(AB17/AC17,"-") -> 0.66436435 | AI17: AA | AJ17: =AVERAGEIFS($M$3:$M$290,$J$3:$J$290,AI17)-$AJ$3 -> 0.041354167 | AK17: AB | AL17: =AVERAGEIFS($M$3:$M$290,$K$3:$K$290,AK17)-$AJ$3 -> -0.3409375 | AM17: AB | AN17: =AVERAGEIFS($M$3:$M$290,$L$3:$L$290,AM17)-$AJ$3 -> -0.34628472 | AO17: AAB | AP17: =AVERAGEIFS($M$3:$M$290,$F$3:$F$290,AO17)-$AJ$3 -> -0.64114583
B18: 01 | C18: 04 | D18: =B18&C18 -> 0104 | E18: 09 | F18: =VLOOKUP(E18,'Base Original'!$B$4:$C$16,2,0) -> CBB | G18: =LEFT(F18,1) -> C | H18: =MID(F18,2,1) -> B | I18: =RIGHT(F18,1) -> B | J18: =G18&H18 -> CB | K18: =G18&I18 -> CB | L18: =H18&I18 -> BB | M18: 23.77 | R18: 01 | S18: =SUMIFS($M$3:$M$290,$C$3:$C$290,R4) -> 569.84 | T18: =S18^2 -> 324717.63 | U18: 24 | AA18: Total | AB18: =SUM($R$95:$R$382) -> 267.59807 | AC18: =X4-1 -> 287 | AI18: AB | AJ18: =AVERAGEIFS($M$3:$M$290,$J$3:$J$290,AI18)-$AJ$3 -> 0.30010417 | AK18: CA | AL18: =AVERAGEIFS($M$3:$M$290,$K$3:$K$290,AK18)-$AJ$3 -> -0.12802083 | AM18: BB | AN18: =AVERAGEIFS($M$3:$M$290,$L$3:$L$290,AM18)-$AJ$3 -> -0.14086806 | AO18: ABB | AP18: =AVERAGEIFS($M$3:$M$290,$F$3:$F$290,AO18)-$AJ$3 -> -0.040729167
B19: 01 | C19: 05 | D19: =B19&C19 -> 0105 | E19: 03 | F19: =VLOOKUP(E19,'Base Original'!$B$4:$C$16,2,0) -> CAA | G19: =LEFT(F19,1) -> C | H19: =MID(F19,2,1) -> A | I19: =RIGHT(F19,1) -> A | J19: =G19&H19 -> CA | K19: =G19&I19 -> CA | L19: =H19&I19 -> AA | M19: 23.37 | R19: 02 | S19: =SUMIFS($M$3:$M$290,$C$3:$C$290,R5) -> 576.59 | T19: =S19^2 -> 332456.03 | U19: 24 | AA19: Trat 1 x Demais | AB19: =$S$32^2/$U$32+SUM($S$33:$S$43)^2/SUM($U$33:$U$43)-SUM($S$32:$S$43)^2/$X$4 -> 13.718353 | AC19: 1 | AD19: =AB19/AC19 -> 13.718353 | AE19: =AD19/AD17 -> 20.648839 | AF19: =IFERROR(_xlfn.F.DIST.RT(AE19,AC19,$AC$17),"-") -> 8.5372337e-06 | AI19: CB | AJ19: =AVERAGEIFS($M$3:$M$290,$J$3:$J$290,AI19)-$AJ$3 -> 0.19989583 | AK19: CB | AL19: =AVERAGEIFS($M$3:$M$290,$K$3:$K$290,AK19)-$AJ$3 -> -0.013229167 | AM19: BA | AN19: =AVERAGEIFS($M$3:$M$290,$L$3:$L$290,AM19)-$AJ$3 -> 0.31871528 | AO19: CBA | AP19: =AVERAGEIFS($M$3:$M$290,$F$3:$F$290,AO19)-$AJ$3 -> 0.2009375
B20: 01 | C20: 06 | D20: =B20&C20 -> 0106 | E20: 04 | F20: =VLOOKUP(E20,'Base Original'!$B$4:$C$16,2,0) -> ABA | G20: =LEFT(F20,1) -> A | H20: =MID(F20,2,1) -> B | I20: =RIGHT(F20,1) -> A | J20: =G20&H20 -> AB | K20: =G20&I20 -> AA | L20: =H20&I20 -> BA | M20: 24.9 | R20: 03 | S20: =SUMIFS($M$3:$M$290,$C$3:$C$290,R6) -> 578.23 | T20: =S20^2 -> 334349.93 | U20: 24 | AI20: CA | AJ20: =AVERAGEIFS($M$3:$M$290,$J$3:$J$290,AI20)-$AJ$3 -> -0.34114583 | AK20: AA | AL20: =AVERAGEIFS($M$3:$M$290,$K$3:$K$290,AK20)-$AJ$3 -> 0.68239583 | AM20: AA | AN20: =AVERAGEIFS($M$3:$M$290,$L$3:$L$290,AM20)-$AJ$3 -> 0.1684375 | AO20: CBB | AP20: =AVERAGEIFS($M$3:$M$290,$F$3:$F$290,AO20)-$AJ$3 -> 0.19885417
B21: 01 | C21: 07 | D21: =B21&C21 -> 0107 | E21: 12 | F21: =VLOOKUP(E21,'Base Original'!$B$4:$C$16,2,0) -> CAB | G21: =LEFT(F21,1) -> C | H21: =MID(F21,2,1) -> A | I21: =RIGHT(F21,1) -> B | J21: =G21&H21 -> CA | K21: =G21&I21 -> CB | L21: =H21&I21 -> AB | M21: 23.41 | R21: 04 | S21: =SUMIFS($M$3:$M$290,$C$3:$C$290,R7) -> 577.06 | T21: =S21^2 -> 332998.24 | U21: 24 | AI21: BB | AJ21: =AVERAGEIFS($M$3:$M$290,$J$3:$J$290,AI21)-$AJ$3 -> -0.23322917 | AK21: BA | AL21: =AVERAGEIFS($M$3:$M$290,$K$3:$K$290,AK21)-$AJ$3 -> 0.17635417 | AO21: CAA | AP21: =AVERAGEIFS($M$3:$M$290,$F$3:$F$290,AO21)-$AJ$3 -> -0.45697917
B22: 01 | C22: 08 | D22: =B22&C22 -> 0108 | E22: 05 | F22: =VLOOKUP(E22,'Base Original'!$B$4:$C$16,2,0) -> BBA | G22: =LEFT(F22,1) -> B | H22: =MID(F22,2,1) -> B | I22: =RIGHT(F22,1) -> A | J22: =G22&H22 -> BB | K22: =G22&I22 -> BA | L22: =H22&I22 -> BA | M22: 24.55 | R22: 05 | S22: =SUMIFS($M$3:$M$290,$C$3:$C$290,R8) -> 571.62 | T22: =S22^2 -> 326749.42 | U22: 24 | AI22: BA | AJ22: =AVERAGEIFS($M$3:$M$290,$J$3:$J$290,AI22)-$AJ$3 -> 0.033020833 | AK22: BB | AL22: =AVERAGEIFS($M$3:$M$290,$K$3:$K$290,AK22)-$AJ$3 -> -0.3765625 | AO22: ABA | AP22: =AVERAGEIFS($M$3:$M$290,$F$3:$F$290,AO22)-$AJ$3 -> 0.6409375
B23: 01 | C23: 09 | D23: =B23&C23 -> 0109 | E23: 08 | F23: =VLOOKUP(E23,'Base Original'!$B$4:$C$16,2,0) -> BBB | G23: =LEFT(F23,1) -> B | H23: =MID(F23,2,1) -> B | I23: =RIGHT(F23,1) -> B | J23: =G23&H23 -> BB | K23: =G23&I23 -> BB | L23: =H23&I23 -> BB | M23: 24.33 | R23: 06 | S23: =SUMIFS($M$3:$M$290,$C$3:$C$290,R9) -> 584.73 | T23: =S23^2 -> 341909.17 | U23: 24 | AO23: CAB | AP23: =AVERAGEIFS($M$3:$M$290,$F$3:$F$290,AO23)-$AJ$3 -> -0.2253125
B24: 01 | C24: 10 | D24: =B24&C24 -> 0110 | E24: 02 | F24: =VLOOKUP(E24,'Base Original'!$B$4:$C$16,2,0) -> BAA | G24: =LEFT(F24,1) -> B | H24: =MID(F24,2,1) -> A | I24: =RIGHT(F24,1) -> A | J24: =G24&H24 -> BA | K24: =G24&I24 -> BA | L24: =H24&I24 -> AA | M24: 24.52 | R24: 07 | S24: =SUMIFS($M$3:$M$290,$C$3:$C$290,R10) -> 586.35 | T24: =S24^2 -> 343806.32 | U24: 24 | AO24: BBA | AP24: =AVERAGEIFS($M$3:$M$290,$F$3:$F$290,AO24)-$AJ$3 -> 0.11427083
B25: 01 | C25: 11 | D25: =B25&C25 -> 0111 | E25: 01 | F25: =VLOOKUP(E25,'Base Original'!$B$4:$C$16,2,0) -> AAA | G25: =LEFT(F25,1) -> A | H25: =MID(F25,2,1) -> A | I25: =RIGHT(F25,1) -> A | J25: =G25&H25 -> AA | K25: =G25&I25 -> AA | L25: =H25&I25 -> AA | M25: 26.13 | R25: 08 | S25: =SUMIFS($M$3:$M$290,$C$3:$C$290,R11) -> 576.56 | T25: =S25^2 -> 332421.43 | U25: 24 | AO25: BBB | AP25: =AVERAGEIFS($M$3:$M$290,$F$3:$F$290,AO25)-$AJ$3 -> -0.58072917
B26: 01 | C26: 12 | D26: =B26&C26 -> 0112 | E26: 11 | F26: =VLOOKUP(E26,'Base Original'!$B$4:$C$16,2,0) -> BAB | G26: =LEFT(F26,1) -> B | H26: =MID(F26,2,1) -> A | I26: =RIGHT(F26,1) -> B | J26: =G26&H26 -> BA | K26: =G26&I26 -> BB | L26: =H26&I26 -> AB | M26: 25.29 | R26: 09 | S26: =SUMIFS($M$3:$M$290,$C$3:$C$290,R12) -> 589.67 | T26: =S26^2 -> 347710.71 | U26: 24 | AO26: BAA | AP26: =AVERAGEIFS($M$3:$M$290,$F$3:$F$290,AO26)-$AJ$3 -> 0.2384375
B27: 02 | C27: 01 | D27: =B27&C27 -> 0201 | E27: 05 | F27: =VLOOKUP(E27,'Base Original'!$B$4:$C$16,2,0) -> BBA | G27: =LEFT(F27,1) -> B | H27: =MID(F27,2,1) -> B | I27: =RIGHT(F27,1) -> A | J27: =G27&H27 -> BB | K27: =G27&I27 -> BA | L27: =H27&I27 -> BA | M27: 25.43 | R27: 10 | S27: =SUMIFS($M$3:$M$290,$C$3:$C$290,R13) -> 587.17 | T27: =S27^2 -> 344768.61 | U27: 24 | AO27: AAA | AP27: =AVERAGEIFS($M$3:$M$290,$F$3:$F$290,AO27)-$AJ$3 -> 0.72385417
B28: 02 | C28: 02 | D28: =B28&C28 -> 0202 | E28: 11 | F28: =VLOOKUP(E28,'Base Original'!$B$4:$C$16,2,0) -> BAB | G28: =LEFT(F28,1) -> B | H28: =MID(F28,2,1) -> A | I28: =RIGHT(F28,1) -> B | J28: =G28&H28 -> BA | K28: =G28&I28 -> BB | L28: =H28&I28 -> AB | M28: 25.3 | R28: 11 | S28: =SUMIFS($M$3:$M$290,$C$3:$C$290,R14) -> 588.31 | T28: =S28^2 -> 346108.66 | U28: 24 | AO28: BAB | AP28: =AVERAGEIFS($M$3:$M$290,$F$3:$F$290,AO28)-$AJ$3 -> -0.17239583
B29: 02 | C29: 03 | D29: =B29&C29 -> 0203 | E29: 03 | F29: =VLOOKUP(E29,'Base Original'!$B$4:$C$16,2,0) -> CAA | G29: =LEFT(F29,1) -> C | H29: =MID(F29,2,1) -> A | I29: =RIGHT(F29,1) -> A | J29: =G29&H29 -> CA | K29: =G29&I29 -> CA | L29: =H29&I29 -> AA | M29: 23.42 | R29: 12 | S29: =SUMIFS($M$3:$M$290,$C$3:$C$290,R15) -> 597.96 | T29: =S29^2 -> 357556.16 | U29: 24
B30: 02 | C30: 04 | D30: =B30&C30 -> 0204 | E30: 04 | F30: =VLOOKUP(E30,'Base Original'!$B$4:$C$16,2,0) -> ABA | G30: =LEFT(F30,1) -> A | H30: =MID(F30,2,1) -> B | I30: =RIGHT(F30,1) -> A | J30: =G30&H30 -> AB | K30: =G30&I30 -> AA | L30: =H30&I30 -> BA | M30: 25.49
B31: 02 | C31: 05 | D31: =B31&C31 -> 0205 | E31: 10 | F31: =VLOOKUP(E31,'Base Original'!$B$4:$C$16,2,0) -> AAB | G31: =LEFT(F31,1) -> A | H31: =MID(F31,2,1) -> A | I31: =RIGHT(F31,1) -> B | J31: =G31&H31 -> AA | K31: =G31&I31 -> AB | L31: =H31&I31 -> AB | M31: 23.56 | R31: Tratamentos | S31: Total | T31: Total^2 | U31: n
B32: 02 | C32: 06 | D32: =B32&C32 -> 0206 | E32: 06 | F32: =VLOOKUP(E32,'Base Original'!$B$4:$C$16,2,0) -> CBA | G32: =LEFT(F32,1) -> C | H32: =MID(F32,2,1) -> B | I32: =RIGHT(F32,1) -> A | J32: =G32&H32 -> CB | K32: =G32&I32 -> CA | L32: =H32&I32 -> BA | M32: 24.07 | R32: 01 | S32: =SUMIFS($M$3:$M$290,$E$3:$E$290,R18) -> 599.38 | T32: =S32^2 -> 359256.38 | U32: 24
B33: 02 | C33: 07 | D33: =B33&C33 -> 0207 | E33: 01 | F33: =VLOOKUP(E33,'Base Original'!$B$4:$C$16,2,0) -> AAA | G33: =LEFT(F33,1) -> A | H33: =MID(F33,2,1) -> A | I33: =RIGHT(F33,1) -> A | J33: =G33&H33 -> AA | K33: =G33&I33 -> AA | L33: =H33&I33 -> AA | M33: 25.63 | R33: 02 | S33: =SUMIFS($M$3:$M$290,$E$3:$E$290,R19) -> 587.73 | T33: =S33^2 -> 345426.55 | U33: 24
B34: 02 | C34: 08 | D34: =B34&C34 -> 0208 | E34: 07 | F34: =VLOOKUP(E34,'Base Original'!$B$4:$C$16,2,0) -> ABB | G34: =LEFT(F34,1) -> A | H34: =MID(F34,2,1) -> B | I34: =RIGHT(F34,1) -> B | J34: =G34&H34 -> AB | K34: =G34&I34 -> AB | L34: =H34&I34 -> BB | M34: 24.36 | R34: 03 | S34: =SUMIFS($M$3:$M$290,$E$3:$E$290,R20) -> 571.04 | T34: =S34^2 -> 326086.68 | U34: 24
B35: 02 | C35: 09 | D35: =B35&C35 -> 0209 | E35: 12 | F35: =VLOOKUP(E35,'Base Original'!$B$4:$C$16,2,0) -> CAB | G35: =LEFT(F35,1) -> C | H35: =MID(F35,2,1) -> A | I35: =RIGHT(F35,1) -> B | J35: =G35&H35 -> CA | K35: =G35&I35 -> CB | L35: =H35&I35 -> AB | M35: 24.55 | R35: 04 | S35: =SUMIFS($M$3:$M$290,$E$3:$E$290,R21) -> 597.39 | T35: =S35^2 -> 356874.81 | U35: 24
B36: 02 | C36: 10 | D36: =B36&C36 -> 0210 | E36: 08 | F36: =VLOOKUP(E36,'Base Original'!$B$4:$C$16,2,0) -> BBB | G36: =LEFT(F36,1) -> B | H36: =MID(F36,2,1) -> B | I36: =RIGHT(F36,1) -> B | J36: =G36&H36 -> BB | K36: =G36&I36 -> BB | L36: =H36&I36 -> BB | M36: 24.04 | R36: 05 | S36: =SUMIFS($M$3:$M$290,$E$3:$E$290,R22) -> 584.75 | T36: =S36^2 -> 341932.56 | U36: 24
B37: 02 | C37: 11 | D37: =B37&C37 -> 0211 | E37: 09 | F37: =VLOOKUP(E37,'Base Original'!$B$4:$C$16,2,0) -> CBB | G37: =LEFT(F37,1) -> C | H37: =MID(F37,2,1) -> B | I37: =RIGHT(F37,1) -> B | J37: =G37&H37 -> CB | K37: =G37&I37 -> CB | L37: =H37&I37 -> BB | M37: 24.08 | R37: 06 | S37: =SUMIFS($M$3:$M$290,$E$3:$E$290,R23) -> 586.83 | T37: =S37^2 -> 344369.45 | U37: 24
B38: 02 | C38: 12 | D38: =B38&C38 -> 0212 | E38: 02 | F38: =VLOOKUP(E38,'Base Original'!$B$4:$C$16,2,0) -> BAA | G38: =LEFT(F38,1) -> B | H38: =MID(F38,2,1) -> A | I38: =RIGHT(F38,1) -> A | J38: =G38&H38 -> BA | K38: =G38&I38 -> BA | L38: =H38&I38 -> AA | M38: 24.18 | R38: 07 | S38: =SUMIFS($M$3:$M$290,$E$3:$E$290,R24) -> 581.03 | T38: =S38^2 -> 337595.86 | U38: 24
B39: 02 | C39: 01 | D39: =B39&C39 -> 0201 | E39: 05 | F39: =VLOOKUP(E39,'Base Original'!$B$4:$C$16,2,0) -> BBA | G39: =LEFT(F39,1) -> B | H39: =MID(F39,2,1) -> B | I39: =RIGHT(F39,1) -> A | J39: =G39&H39 -> BB | K39: =G39&I39 -> BA | L39: =H39&I39 -> BA | M39: 23.46 | R39: 08 | S39: =SUMIFS($M$3:$M$290,$E$3:$E$290,R25) -> 568.07 | T39: =S39^2 -> 322703.52 | U39: 24
B40: 02 | C40: 02 | D40: =B40&C40 -> 0202 | E40: 11 | F40: =VLOOKUP(E40,'Base Original'!$B$4:$C$16,2,0) -> BAB | G40: =LEFT(F40,1) -> B | H40: =MID(F40,2,1) -> A | I40: =RIGHT(F40,1) -> B | J40: =G40&H40 -> BA | K40: =G40&I40 -> BB | L40: =H40&I40 -> AB | M40: 23.7 | R40: 09 | S40: =SUMIFS($M$3:$M$290,$E$3:$E$290,R26) -> 586.78 | T40: =S40^2 -> 344310.77 | U40: 24
...
